---
title: TypeScript Try Catch
description: 学习如何在 TypeScript 中使用 try-catch 语句处理错误，掌握异常处理的基本概念和实际应用场景。
---

# TypeScript Try Catch

在编程中，错误处理是一个非常重要的部分。无论代码多么完美，总会有一些不可预见的情况导致程序出错。TypeScript 提供了 `try-catch` 语句来帮助我们捕获和处理这些错误，从而避免程序崩溃。

## 什么是 Try Catch？

`try-catch` 是一种异常处理机制，允许你在代码中捕获并处理运行时错误。`try` 块中包含可能会抛出错误的代码，而 `catch` 块则用于捕获并处理这些错误。

### 基本语法

```typescript
try {
  // 可能会抛出错误的代码
} catch (error) {
  // 处理错误的代码
}
```

### 示例

让我们来看一个简单的例子：

```typescript
function divide(a: number, b: number): number {
  if (b === 0) {
    throw new Error("除数不能为零");
  }
  return a / b;
}

try {
  const result = divide(10, 0);
  console.log(result);
} catch (error) {
  console.error("捕获到错误:", error.message);
}
```

**输出：**

```
捕获到错误: 除数不能为零
```

在这个例子中，我们定义了一个 `divide` 函数，用于计算两个数的商。如果除数为零，函数会抛出一个错误。在 `try` 块中调用这个函数时，如果发生错误，`catch` 块会捕获并处理这个错误。

## 逐步讲解

### 1. `try` 块

`try` 块中包含可能会抛出错误的代码。如果 `try` 块中的代码执行时没有抛出任何错误，那么 `catch` 块将被跳过。

### 2. `catch` 块

`catch` 块用于捕获 `try` 块中抛出的错误。`catch` 块中的代码只有在 `try` 块中抛出错误时才会执行。`catch` 块接收一个参数，通常是 `error`，它包含了抛出的错误信息。

### 3. `throw` 语句

`throw` 语句用于抛出一个错误。你可以抛出一个字符串、数字、对象或 `Error` 对象。通常，我们使用 `Error` 对象来抛出错误，因为它包含了更多的信息，如错误消息和堆栈跟踪。

```typescript
throw new Error("这是一个错误消息");
```

### 4. `finally` 块

`finally` 块是可选的，它会在 `try` 块和 `catch` 块执行完毕后执行，无论是否抛出错误。`finally` 块通常用于释放资源或执行清理操作。

```typescript
try {
  // 可能会抛出错误的代码
} catch (error) {
  // 处理错误的代码
} finally {
  // 无论是否抛出错误，都会执行的代码
}
```

## 实际案例

### 文件读取

假设我们有一个函数用于读取文件内容。如果文件不存在，函数会抛出一个错误。我们可以使用 `try-catch` 来处理这种情况。

```typescript
import * as fs from 'fs';

function readFile(path: string): string {
  if (!fs.existsSync(path)) {
    throw new Error("文件不存在");
  }
  return fs.readFileSync(path, 'utf8');
}

try {
  const content = readFile("example.txt");
  console.log(content);
} catch (error) {
  console.error("捕获到错误:", error.message);
}
```

**输出：**

```
捕获到错误: 文件不存在
```

### 网络请求

在处理网络请求时，可能会遇到各种错误，如网络连接问题、服务器错误等。我们可以使用 `try-catch` 来捕获这些错误。

```typescript
async function fetchData(url: string): Promise<any> {
  const response = await fetch(url);
  if (!response.ok) {
    throw new Error("网络请求失败");
  }
  return response.json();
}

try {
  const data = await fetchData("https://api.example.com/data");
  console.log(data);
} catch (error) {
  console.error("捕获到错误:", error.message);
}
```

**输出：**

```
捕获到错误: 网络请求失败
```

## 总结

`try-catch` 是 TypeScript 中处理错误的强大工具。通过使用 `try-catch`，你可以捕获并处理运行时错误，从而避免程序崩溃。在实际开发中，合理使用 `try-catch` 可以提高代码的健壮性和可维护性。

## 附加资源

- [TypeScript 官方文档](https://www.typescriptlang.org/docs/)
- [MDN Web Docs: try...catch](https://developer.mozilla.org/en-US/docs/Web/JavaScript/Reference/Statements/try...catch)

## 练习

1. 编写一个函数，用于计算两个数的乘积。如果其中一个数为负数，抛出错误并使用 `try-catch` 捕获。
2. 修改上面的文件读取示例，使其在 `finally` 块中输出一条消息，表示文件读取操作已完成。

通过完成这些练习，你将更好地理解 `try-catch` 的使用场景和实际应用。