---
title: Python Finally子句
description: 学习Python中finally子句的使用方法，了解为什么它在异常处理中很重要，以及如何在实际场景中正确应用它。
---

# Python Finally子句

## 介绍

在Python的异常处理机制中，`finally`子句是一个强大而实用的工具。无论异常是否发生，`finally`块中的代码总是会被执行，这使得它成为执行清理操作的理想选择，例如关闭文件、释放资源或断开数据库连接等。

本教程将帮助你理解`finally`子句的工作原理，以及如何在实际编程中有效地使用它。

## finally子句的基本语法

`finally`子句通常与`try`和`except`块一起使用，形成完整的异常处理结构：

```python
try:
    # 可能引发异常的代码
    ...
except SomeException:
    # 处理特定异常的代码
    ...
finally:
    # 无论是否发生异常，都会执行的代码
    ...
```

也可以不使用`except`块，直接使用`try`和`finally`：

```python
try:
    # 可能引发异常的代码
    ...
finally:
    # 无论是否发生异常，都会执行的代码
    ...
```

## finally子句的执行顺序

为了理解`finally`子句的执行流程，让我们看一个简单的例子：

```python
def finally_demo(x):
    try:
        result = 100 / x
        print(f"计算结果: {result}")
        return result
    except ZeroDivisionError:
        print("错误: 除数不能为零")
        return None
    finally:
        print("finally块被执行")

# 测试不同情况
print("Case 1: x = 10")
finally_demo(10)

print("\nCase 2: x = 0")
finally_demo(0)
```

输出结果：
```
Case 1: x = 10
计算结果: 10.0
finally块被执行

Case 2: x = 0
错误: 除数不能为零
finally块被执行
```

:::note
注意在两种情况下，无论是正常执行还是发生异常，`finally`块中的代码都被执行了。
:::

## finally子句与return语句

`finally`块即使在`try`或`except`块中有`return`语句时也会执行，这是它的一个重要特性：

```python
def return_demo():
    try:
        print("在try块中")
        return "try的返回值"
    finally:
        print("在finally块中")

result = return_demo()
print(f"函数返回值: {result}")
```

输出结果：
```
在try块中
在finally块中
函数返回值: try的返回值
```

然而，需要注意的是，如果`finally`块中也包含`return`语句，它将覆盖`try`和`except`块中的返回值：

```python
def override_return():
    try:
        print("在try块中")
        return "try的返回值"
    finally:
        print("在finally块中")
        return "finally的返回值"  # 这将覆盖try中的返回值

result = override_return()
print(f"函数返回值: {result}")
```

输出结果：
```
在try块中
在finally块中
函数返回值: finally的返回值
```

:::caution
在`finally`块中使用`return`语句可能会导致意外的行为，因为它会覆盖`try`和`except`块中的返回值。除非你明确知道自己在做什么，否则最好避免在`finally`块中使用`return`语句。
:::

## 实际应用场景

### 场景1：文件操作

`finally`子句最常见的用途之一是确保文件在使用后被正确关闭，无论是否发生异常：

```python
def read_file(filename):
    file = None
    try:
        file = open(filename, 'r')
        content = file.read()
        return content
    except FileNotFoundError:
        print(f"错误: 文件'{filename}'不存在")
        return None
    finally:
        if file:
            file.close()
            print(f"文件'{filename}'已关闭")

# 测试存在的文件
print(read_file('existing_file.txt'))  # 假设这个文件存在

# 测试不存在的文件
print(read_file('non_existing_file.txt'))
```

:::tip
虽然上面的例子展示了如何使用`finally`确保文件关闭，但在实际Python编程中，使用`with`语句（上下文管理器）是处理文件操作的更好方式，因为它会自动处理文件的关闭：

```python
def read_file_better(filename):
    try:
        with open(filename, 'r') as file:
            return file.read()
    except FileNotFoundError:
        print(f"错误: 文件'{filename}'不存在")
        return None
```
:::

### 场景2：数据库连接

确保数据库连接在使用后被正确关闭：

```python
import sqlite3

def query_database():
    connection = None
    cursor = None
    try:
        connection = sqlite3.connect('example.db')
        cursor = connection.cursor()
        
        # 执行查询
        cursor.execute('SELECT * FROM users')
        return cursor.fetchall()
    except sqlite3.Error as e:
        print(f"数据库错误: {e}")
        return None
    finally:
        if cursor:
            cursor.close()
        if connection:
            connection.close()
            print("数据库连接已关闭")
```

### 场景3：锁的释放

在多线程程序中，确保锁在使用后被释放：

```python
import threading

def thread_safe_operation(lock, shared_resource):
    try:
        lock.acquire()
        # 修改共享资源
        shared_resource.append(1)
        print(f"资源现在是: {shared_resource}")
    finally:
        lock.release()
        print("锁已释放")
```

## finally子句与异常传播

如果`try`块中的异常没有被`except`块捕获，或者`except`块中又引发了新的异常，那么在`finally`块执行后，异常会继续向上传播：

```python
def exception_propagation():
    try:
        print("在try块中")
        1 / 0  # 触发 ZeroDivisionError
    finally:
        print("在finally块中")
        
    print("这行代码不会执行")  # 这行永远不会执行

try:
    exception_propagation()
except ZeroDivisionError:
    print("捕获到除零错误")
```

输出结果：
```
在try块中
在finally块中
捕获到除零错误
```

## 嵌套的try-finally块

`try-finally`结构可以嵌套使用，每个`finally`块都会按照其嵌套顺序的相反方向执行：

```python
def nested_finally():
    try:
        print("外层try块")
        try:
            print("内层try块")
            1 / 0  # 引发异常
        finally:
            print("内层finally块")
    finally:
        print("外层finally块")

try:
    nested_finally()
except ZeroDivisionError:
    print("捕获到除零错误")
```

输出结果：
```
外层try块
内层try块
内层finally块
外层finally块
捕获到除零错误
```

## 总结

`finally`子句是Python异常处理机制中的重要组成部分，它提供了一种无论是否发生异常都能执行特定代码的方式。主要特点包括：

1. 无论是否发生异常，`finally`块中的代码总是会执行
2. 即使在`try`或`except`块中有`return`语句，`finally`块也会执行
3. 如果`finally`块中有`return`语句，它会覆盖`try`和`except`块中的返回值
4. `finally`块常用于资源清理，如关闭文件、释放数据库连接等

掌握`finally`子句的使用对于编写健壮的Python代码至关重要，尤其是在处理需要适当清理的资源时。

## 练习

1. 编写一个函数，使用`try-except-finally`结构从文件中读取整数，并处理可能的`ValueError`和`FileNotFoundError`异常。

2. 修改下面的代码，使其正确处理资源清理：
   ```python
   def process_data():
       file = open("data.txt", "r")
       data = file.read()
       result = int(data)
       return result
   ```

3. 创建一个函数，演示`finally`块中的`return`语句如何覆盖`try`和`except`块中的返回值，并思考这种模式的潜在问题。

## 进一步阅读

- Python官方文档中关于[异常处理](https://docs.python.org/3/tutorial/errors.html)的部分
- 了解Python的[上下文管理器](https://docs.python.org/3/reference/datamodel.html#context-managers)和[with语句](https://docs.python.org/3/reference/compound_stmts.html#with)，它们提供了比手动使用`try-finally`更优雅的资源管理方式

通过理解和正确使用`finally`子句，你可以编写出更健壮、更易维护的Python代码，特别是在处理需要清理的资源时。